<?xml version="1.0" ?>
<robot name="pupper_ros">

<material name="black">
  <color rgba="0.1 0.1 0.1 1.0"/>
</material>

<material name="blue">
  <color rgba="0.3 0.5 0.9 1.0"/>
</material>


<material name="red">
  <color rgba="0.5 0.1 0.1 1.0"/>
</material>

<!--  TORSO   -->


  <link name="torso" type="fixed">
      <visual>
        <origin rpy="0 0 0" xyz="0.0 0.0 0.4"/>
        <geometry>
          <box size="0.26 0.26 0.15"/>
        </geometry>
          <material name="blue"/>
      </visual>
  </link>

<!-- Shoulders -->

<!-- Front right -->

  <joint name="shldr_f_r_joint" type="continuous">
    <parent link="torso"/>
    <child link="shldr_f_r_1"/>
    <origin rpy="0 1.57 0" xyz="0.18 -0.1 0.4"/>
    <axis xyz="0 0 1"/>
  </joint>

  <link name="shldr_f_r_1">
    <visual>
      <origin rpy="0 0 0" xyz="0 0 0"/>
      <geometry>
        <cylinder radius="0.05" length="0.1"/>
      </geometry>
        <material name="black"/>
    </visual>
  </link>

  <joint name="shldr_f_r_joint_inter" type="fixed">
    <parent link="shldr_f_r_1"/>
    <child link="shldr_f_r_2"/>
    <origin rpy="0 1.57 1.57" xyz="0 -0.06 0.1"/>
    <axis xyz="0 0 1"/>
  </joint>

  <link name="shldr_f_r_2">
    <visual>
      <origin rpy="0 0 0" xyz="0 0 0"/>
      <geometry>
        <cylinder radius="0.05" length="0.066"/>
      </geometry>
        <material name="black"/>
    </visual>
  </link>

<!-- Front left -->

<joint name="shldr_f_l_joint" type="continuous">
    <parent link="torso"/>
    <child link="shldr_f_l_1"/>
    <origin rpy="0 1.57 0" xyz="0.18 0.1 0.4"/>
    <axis xyz="0 0 1"/>
  </joint>

  <link name="shldr_f_l_1">
    <visual>
      <origin rpy="0 0 0" xyz="0 0 0"/>
      <geometry>
        <cylinder radius="0.05" length="0.1"/>
      </geometry>
        <material name="black"/>
    </visual>
  </link>

  <joint name="shldr_f_l_joint_inter" type="fixed">
    <parent link="shldr_f_l_1"/>
    <child link="shldr_f_l_2"/>
    <origin rpy="0 1.57 1.57" xyz="0 0.06 0.1"/>
    <axis xyz="0 0 1"/>
  </joint>

  <link name="shldr_f_l_2">
    <visual>
      <origin rpy="0 0 0" xyz="0 0 0"/>
      <geometry>
        <cylinder radius="0.05" length="0.066"/>
      </geometry>
        <material name="black"/>
    </visual>
  </link>

<!-- Back right -->

<joint name="shldr_b_r_joint" type="continuous">
    <parent link="torso"/>
    <child link="shldr_b_r_1"/>
    <origin rpy="0 1.57 0" xyz="-0.18 -0.1 0.4"/>
    <axis xyz="0 0 1"/>
  </joint>

  <link name="shldr_b_r_1">
    <visual>
      <origin rpy="0 0 0" xyz="0 0 0"/>
      <geometry>
        <cylinder radius="0.05" length="0.1"/>
      </geometry>
        <material name="black"/>
    </visual>
  </link>

  <joint name="shldr_b_r_joint_inter" type="fixed">
    <parent link="shldr_b_r_1"/>
    <child link="shldr_b_r_2"/>
    <origin rpy="0 1.57 1.57" xyz="0 -0.06 -0.1"/>
    <axis xyz="0 0 1"/>
  </joint>

  <link name="shldr_b_r_2">
    <visual>
      <origin rpy="0 0 0" xyz="0 0 0"/>
      <geometry>
        <cylinder radius="0.05" length="0.066"/>
      </geometry>
        <material name="black"/>
    </visual>
  </link>

<!-- Back left -->

<joint name="shldr_b_l_joint" type="continuous">
    <parent link="torso"/>
    <child link="shldr_b_l_1"/>
    <origin rpy="0 1.57 0" xyz="-0.18 0.1 0.4"/>
    <axis xyz="0 0 1"/>
  </joint>

  <link name="shldr_b_l_1">
    <visual>
      <origin rpy="0 0 0" xyz="0 0 0"/>
      <geometry>
        <cylinder radius="0.05" length="0.1"/>
      </geometry>
        <material name="black"/>
    </visual>
  </link>

  <joint name="shldr_b_l_joint_inter" type="fixed">
    <parent link="shldr_b_l_1"/>
    <child link="shldr_b_l_2"/>
    <origin rpy="0 1.57 1.57" xyz="0 0.06 -0.1"/>
    <axis xyz="0 0 1"/>
  </joint>

  <link name="shldr_b_l_2">
    <visual>
      <origin rpy="0 0 0" xyz="0 0 0"/>
      <geometry>
        <cylinder radius="0.05" length="0.066"/>
      </geometry>
        <material name="black"/>
    </visual>
  </link>

  <!-- forearms -->

  <joint name="forearm_f_r_joint" type="continuous">
    <parent link="shldr_f_r_2"/>
    <child link="forearm_f_r"/>
    <origin rpy="0 0 0" xyz="0 0 0"/>
    <axis xyz="0 1 0"/>
  </joint>

  <link name="forearm_f_r">
    <visual>
      <origin rpy="0 0 1.57" xyz="0 -0.12 0"/>
      <geometry>
        <box size="0.202 0.05 0.03"/>
      </geometry>
        <material name="blue"/>
    </visual>
  </link>

  <joint name="forearm_f_l_joint" type="continuous">
    <parent link="shldr_f_l_2"/>
    <child link="forearm_f_l"/>
    <origin rpy="0 0 0" xyz="0 0 0"/>
    <axis xyz="0 1 0"/>
  </joint>

  <link name="forearm_f_l">
    <visual>
      <origin rpy="0 0 1.57" xyz="0 -0.12 0"/>
      <geometry>
        <box size="0.202 0.05 0.03"/>
      </geometry>
        <material name="blue"/>
    </visual>
  </link>

  <joint name="forearm_b_r_joint" type="continuous">
    <parent link="shldr_b_r_2"/>
    <child link="forearm_b_r"/>
    <origin rpy="0 0 0" xyz="0 0 0"/>
    <axis xyz="0 1 0"/>
  </joint>

  <link name="forearm_b_r">
    <visual>
      <origin rpy="0 0 1.57" xyz="0 -0.12 0"/>
      <geometry>
        <box size="0.202 0.05 0.03"/>
      </geometry>
        <material name="blue"/>
    </visual>
  </link>

  <joint name="forearm_b_l_joint" type="continuous">
    <parent link="shldr_b_l_2"/>
    <child link="forearm_b_l"/>
    <origin rpy="0 0 0" xyz="0 0 0"/>
    <axis xyz="0 1 0"/>
  </joint>

  <link name="forearm_b_l">
    <visual>
      <origin rpy="0 0 1.57" xyz="0 -0.12 0"/>
      <geometry>
        <box size="0.202 0.05 0.03"/>
      </geometry>
        <material name="blue"/>
    </visual>
  </link>

  <!-- Legs  -->

  <!-- Front right -->

  <joint name="leg_f_r_joint" type="continuous">
    <parent link="forearm_f_r"/>
    <child link="leg_f_r_knee"/>
    <origin rpy="0 0 0" xyz="0 -0.23 0"/>
    <axis xyz="0 1 0"/>
  </joint>

  <link name="leg_f_r_knee">
    <visual>
      <origin rpy="0 0 0.0" xyz="0 0 0"/>
      <geometry>
        <cylinder radius="0.05" length="0.066"/>
      </geometry>
        <material name="black"/>
    </visual>
  </link>

  <joint name="leg_f_r_knee_joint" type="fixed">
    <parent link="leg_f_r_knee"/>
    <child link="leg_f_r"/>
    <origin rpy="0 0 0" xyz="0 0 0"/>
    <axis xyz="0 1 0"/>
  </joint>

  <link name="leg_f_r">
    <visual>
      <origin rpy="0 0 1.57" xyz="0 -0.12 0"/>
      <geometry>
        <box size="0.177 0.05 0.03"/>
      </geometry>
        <material name="blue"/>
    </visual>
  </link>

<!-- Front left -->

<joint name="leg_f_l_joint" type="continuous">
    <parent link="forearm_f_l"/>
    <child link="leg_f_l_knee"/>
    <origin rpy="0 0 0" xyz="0 -0.23 0"/>
    <axis xyz="0 1 0"/>
  </joint>

  <link name="leg_f_l_knee">
    <visual>
      <origin rpy="0 0 0.0" xyz="0 0 0"/>
      <geometry>
        <cylinder radius="0.05" length="0.066"/>
      </geometry>
        <material name="black"/>
    </visual>
  </link>

  <joint name="leg_f_l_knee_joint" type="fixed">
    <parent link="leg_f_l_knee"/>
    <child link="leg_f_l"/>
    <origin rpy="0 0 0" xyz="0 0 0"/>
    <axis xyz="0 1 0"/>
  </joint>

  <link name="leg_f_l">
    <visual>
      <origin rpy="0 0 1.57" xyz="0 -0.12 0"/>
      <geometry>
        <box size="0.177 0.05 0.03"/>
      </geometry>
        <material name="blue"/>
    </visual>
  </link>

<!-- Back right -->

  <joint name="leg_b_r_joint" type="continuous">
    <parent link="forearm_b_r"/>
    <child link="leg_b_r_knee"/>
    <origin rpy="0 0 0" xyz="0 -0.23 0"/>
    <axis xyz="0 1 0"/>
  </joint>

  <link name="leg_b_r_knee">
    <visual>
      <origin rpy="0 0 0.0" xyz="0 0 0"/>
      <geometry>
        <cylinder radius="0.05" length="0.066"/>
      </geometry>
        <material name="black"/>
    </visual>
  </link>

  <joint name="leg_b_r_knee_joint" type="fixed">
    <parent link="leg_b_r_knee"/>
    <child link="leg_b_r"/>
    <origin rpy="0 0 0" xyz="0 0 0"/>
    <axis xyz="0 1 0"/>
  </joint>

  <link name="leg_b_r">
    <visual>
      <origin rpy="0 0 1.57" xyz="0 -0.12 0"/>
      <geometry>
        <box size="0.177 0.05 0.03"/>
      </geometry>
        <material name="blue"/>
    </visual>
  </link>

<!-- Back left -->

  <joint name="leg_b_l_joint" type="continuous">
    <parent link="forearm_b_l"/>
    <child link="leg_b_l_knee"/>
    <origin rpy="0 0 0" xyz="0 -0.23 0"/>
    <axis xyz="0 1 0"/>
  </joint>

  <link name="leg_b_l_knee">
    <visual>
      <origin rpy="0 0 0.0" xyz="0 0 0"/>
      <geometry>
        <cylinder radius="0.05" length="0.066"/>
      </geometry>
        <material name="black"/>
    </visual>
  </link>

  <joint name="leg_b_l_knee_joint" type="fixed">
    <parent link="leg_b_l_knee"/>
    <child link="leg_b_l"/>
    <origin rpy="0 0 0" xyz="0 0 0"/>
    <axis xyz="0 1 0"/>
  </joint>

  <link name="leg_b_l">
    <visual>
      <origin rpy="0 0 1.57" xyz="0 -0.12 0"/>
      <geometry>
        <box size="0.177 0.05 0.03"/>
      </geometry>
        <material name="blue"/>
    </visual>
  </link>

<!-- Feet -->

  <joint name="leg_f_r_foot_joint" type="fixed">
    <parent link="leg_f_r"/>
    <child link="leg_f_r_foot"/>
    <origin rpy="0 0 0" xyz="0 -0.197 0"/>
    <axis xyz="0 0 0"/>
  </joint>

  <link name="leg_f_r_foot">
    <visual>
      <origin rpy="0 0 0" xyz="0 0 0"/>
      <geometry>
        <sphere radius="0.04"/>
      </geometry>
        <material name="black"/>
    </visual>
  </link>

  <joint name="leg_f_l_foot_joint" type="fixed">
    <parent link="leg_f_l"/>
    <child link="leg_f_l_foot"/>
    <origin rpy="0 0 0" xyz="0 -0.197 0"/>
    <axis xyz="0 0 0"/>
  </joint>

  <link name="leg_f_l_foot">
    <visual>
      <origin rpy="0 0 0" xyz="0 0 0"/>
      <geometry>
        <sphere radius="0.04"/>
      </geometry>
        <material name="black"/>
    </visual>
  </link>

  <joint name="leg_b_l_foot_joint" type="fixed">
    <parent link="leg_b_l"/>
    <child link="leg_b_l_foot"/>
    <origin rpy="0 0 0" xyz="0 -0.197 0"/>
    <axis xyz="0 0 0"/>
  </joint>

  <link name="leg_b_l_foot">
    <visual>
      <origin rpy="0 0 0" xyz="0 0 0"/>
      <geometry>
        <sphere radius="0.04"/>
      </geometry>
        <material name="black"/>
    </visual>
  </link>

  <joint name="leg_b_r_foot_joint" type="fixed">
    <parent link="leg_b_r"/>
    <child link="leg_b_r_foot"/>
    <origin rpy="0 0 0" xyz="0 -0.197 0"/>
    <axis xyz="0 0 0"/>
  </joint>

  <link name="leg_b_r_foot">
    <visual>
      <origin rpy="0 0 0" xyz="0 0 0"/>
      <geometry>
        <sphere radius="0.04"/>
      </geometry>
        <material name="black"/>
    </visual>
  </link>


</robot>
